no change     /home/sophia435256/workspace2/miniconda3/condabin/conda
no change     /home/sophia435256/workspace2/miniconda3/bin/conda
no change     /home/sophia435256/workspace2/miniconda3/bin/conda-env
no change     /home/sophia435256/workspace2/miniconda3/bin/activate
no change     /home/sophia435256/workspace2/miniconda3/bin/deactivate
no change     /home/sophia435256/workspace2/miniconda3/etc/profile.d/conda.sh
no change     /home/sophia435256/workspace2/miniconda3/etc/fish/conf.d/conda.fish
no change     /home/sophia435256/workspace2/miniconda3/shell/condabin/Conda.psm1
no change     /home/sophia435256/workspace2/miniconda3/shell/condabin/conda-hook.ps1
no change     /home/sophia435256/workspace2/miniconda3/lib/python3.12/site-packages/xontrib/conda.xsh
no change     /home/sophia435256/workspace2/miniconda3/etc/profile.d/conda.csh
no change     /home/sophia435256/.bashrc
No action taken.

CondaError: Run 'conda init' before 'conda activate'

WARNING:2025-09-28 20:57:15,847:jax._src.xla_bridge:794: An NVIDIA GPU may be present on this machine, but a CUDA-enabled jaxlib is not installed. Falling back to cpu.
wandb: WARNING `start_method` is deprecated and will be removed in a future version of wandb. This setting is currently non-functional and safely ignored.
Traceback (most recent call last):
  File "/NAS2/sophia435256/fql/main.py", line 223, in <module>
    app.run(main)
  File "/home/sophia435256/workspace2/miniconda3/envs/fql/lib/python3.10/site-packages/absl/app.py", line 316, in run
    _run_main(main, args)
  File "/home/sophia435256/workspace2/miniconda3/envs/fql/lib/python3.10/site-packages/absl/app.py", line 261, in _run_main
    sys.exit(main(argv))
  File "/NAS2/sophia435256/fql/main.py", line 52, in main
    setup_wandb(project='fql', group=FLAGS.run_group, name=exp_name)
  File "/NAS2/sophia435256/fql/utils/log_utils.py", line 89, in setup_wandb
    run = wandb.init(**init_kwargs)
  File "/home/sophia435256/workspace2/miniconda3/envs/fql/lib/python3.10/site-packages/wandb/sdk/wandb_init.py", line 1581, in init
    wandb._sentry.reraise(e)
  File "/home/sophia435256/workspace2/miniconda3/envs/fql/lib/python3.10/site-packages/wandb/analytics/sentry.py", line 162, in reraise
    raise exc.with_traceback(sys.exc_info()[2])
  File "/home/sophia435256/workspace2/miniconda3/envs/fql/lib/python3.10/site-packages/wandb/sdk/wandb_init.py", line 1504, in init
    wi.maybe_login(init_settings)
  File "/home/sophia435256/workspace2/miniconda3/envs/fql/lib/python3.10/site-packages/wandb/sdk/wandb_init.py", line 190, in maybe_login
    wandb_login._login(
  File "/home/sophia435256/workspace2/miniconda3/envs/fql/lib/python3.10/site-packages/wandb/sdk/wandb_login.py", line 318, in _login
    key, key_status = wlogin.prompt_api_key(referrer=referrer)
  File "/home/sophia435256/workspace2/miniconda3/envs/fql/lib/python3.10/site-packages/wandb/sdk/wandb_login.py", line 244, in prompt_api_key
    raise UsageError("api_key not configured (no-tty). call " + directive)
wandb.errors.errors.UsageError: api_key not configured (no-tty). call wandb.login(key=[your_api_key])
